---
title: エラーの発生箇所と処理方法
---

エラーの発生箇所は大きく以下のように分類できます。

- Reactコンポーネント
  - JSX
  - Promise
  - Promise以外（同期処理や`setTimeout`に渡すコールバック関数など）
- イベントハンドラ
  - Promise
  - Promise以外（同期処理や`setTimeout`に渡すコールバック関数など）
- Native Modules

## 未処理のエラーを処理する方法

未処理のエラーは、Firebase Crashlytics SDKがエラーを捕捉してFirebase Crashlyticsにクラッシュログを送信します。

ただし、Promiseで発生したエラーに関しては、Firebase Crashlytics SDKで捕捉できないため、必ず個別にエラー処理を実施してください。

:::warning
JavaScriptエンジンがHermesの場合、iOSではReactコンポーネントで発生したエラーがFirebase Crashlyticsに送信されない事象を確認しています。

回避策として、React.Componentの[componentDidCatch](https://ja.react.dev/reference/react/Component#componentdidcatch)でエラーを再度throwすることで、Firebase Crashlyticsにクラッシュログが送信されます。

詳細は、[FirebaseCrashlyticsWorkaround.tsx](https://github.com/{@inject:organization}/mobile-app-crib-notes/tree/master/example-app/SantokuApp/src/bases/firebase/crashlytics/FirebaseCrashlyticsWorkaround.tsx)を参照してください。
:::

:::caution
Firebase Crashlyticsにログを送信するタイミングは、アプリを再起動した時になります。即座にログが送信されないことに注意してください。
:::

### Firebase Crashlyticsの設定

Firebase Crashlyticsの動作設定は、設定ファイルのFirebase.jsonで以下のように記述することで設定できます。

```json title='Firebase.json'
{
  "react-native": {
    "crashlytics_debug_enabled": false,
    "crashlytics_auto_collection_enabled": true,
    "crashlytics_ndk_enabled": true,
    "crashlytics_is_error_generation_on_js_crash_enabled": false,
    "crashlytics_javascript_exception_handler_chaining_enabled": true
  }
}
```

各パラメーターの定義と効果は、[Crashlytics - Installation and getting started with Crashlytics](https://rnfirebase.io/crashlytics/usage) を参照ください。

## 個別にエラーを処理する方法

### Reactコンポーネントのエラー処理

Reactコンポーネントでは、JSXやコンポーネントのライフサイクルに応じた処理（`componentDidMount`や`useEffect`など）でエラーが発生します。

JSXでエラーが発生した場合は、[Error Boundary](https://ja.react.dev/reference/react/Component#catching-rendering-errors-with-an-error-boundary)でエラーを捕捉します。該当のコンポーネントを`Error Boundary`でラップしてエラー処理を実施してください。

```typescript jsx title='Error Boundaryの例'
const Avator = () => {
  return (
    // アバター表示に失敗した場合は、デフォルトのアバターにフォールバックする
    <AvatorErrorBoundary>
      <ExternalAvator />
    </AvatorErrorBoundary>
  );
};
```

JSXのエラーは基本的にプログラムの不具合によるものです。ほとんどのユースケースにおいて、`Error Boundary`を使用して個別にエラー処理を実施することはないと思われます。

:::note
`Error Boundary`は、イベントハンドラで発生したエラーを捕捉できません。JSX内のイベントハンドラで発生したエラーに関しては、[イベントハンドラのエラー処理](#イベントハンドラのエラー処理)を参照してください。
:::

JSX以外で発生したエラーをハンドリングする場合は、発生元がPromiseかどうかで対応が変わります。

Promiseの場合は、以下のいずれかの方法でエラーを捕捉します。

- `Promise.catch()`を使用してエラーを捕捉します。
- `await`式を利用した場合は`try...catch`文で囲んでエラーを捕捉します。

```typescript jsx title=Promise.catch()の例
const Component = () => {
  useEffect(() => {
    asyncFunction
      .then((value) => {
        // 正常時の処理
      })
      .catch((e) => {
        // エラー処理
      });
  }, [asyncFunction]);

  /* ～省略～ */
};
```

```typescript jsx title=await式を使用した場合のtry...catchの例
const Component = () => {
  const callAsyncFunction = useCallback(async () => {
    try {
      const result = await asyncFunction();
      // 正常時の処理
    } catch (e) {
      // エラー処理
    }
  }, [asyncFunction]);

  useEffect(() => {
    callAsyncFunction().catch(() => {
      // callAsyncFunctionでエラーハンドリングを実施しているので、ここでは特に何もしない
    });
  }, [callAsyncFunction]);

  /* ～省略～ */
};
```

Promise以外の場合は、`try...catch`文で囲んでエラーを捕捉します。`setTimeout`などに渡すコールバック関数では、エラーを関数内で捕捉する必要があることに注意してください。

```typescript jsx title=try...catchの例
const Component = () => {
  useEffect(() => {
    try {
      const result = syncFunction();
      // 正常時の処理
    } catch(e) {
      // エラー処理
    }

    setTimeout(() => {
      // コールバック関数内でエラーを捕捉する
      try {
        const result = syncFunction();
        // 正常時の処理
      } catch(e) {
        // エラー処理
      }
    });
  }, [syncFunction]);

  /* ～省略～ */
};
```

:::note
コンポーネントのライフサイクルに応じた同期処理で発生したエラーも、`Error Boundary`で捕捉できます。しかし、それらのエラーも`Error Boundary`で捕捉してしまうと、個々のエラーに応じた処理を実施することが難しくなります。

そのため、JSX以外の同期処理で発生したエラーについては`Error Boundary`を使用しないで、個別にエラー処理を実施します。
:::

### イベントハンドラのエラー処理

イベントハンドラで発生するエラーを個別にハンドリングする場合は、Reactコンポーネントで説明している内容と同様です。`Promise.catch()`、または`try...catch`を利用してエラーを捕捉してください。

```typescript jsx title=try...catchの例
const Component = () => {
  const syncEventHandler = useCallback(() => {
    try {
      const result = syncFunction();
      // 正常時の処理
    } catch(e) {
      // エラー処理
    }

    setTimeout(() => {
      // コールバック関数内でエラーを捕捉する
      try {
        const result = syncFunction();
        // 正常時の処理
      } catch(e) {
        // エラー処理
      }
    });
  }, [syncFunction]);

  return (
    <View>
      <Button onPress={syncEventHandler} />
    </View>
  );
};
```

```typescript jsx title=Promise.catch()の例
const Component = () => {
  const asyncEventHandler = useCallback(() => {
    asyncFunction
      .then((value) => {
        // 正常時の処理
      })
      .catch((e) => {
        // エラー処理
      });
  }, [asyncFunction]);

  return (
    <View>
      <Button onPress={asyncEventHandler} />
    </View>
  );
};
```

### Native Modulesのエラー処理

Native ModulesはJava（Kotlin）やObjective-C（Swift）、C++などのネイティブ言語を使用したモジュールです。OSが提供しているAPIなどを利用する時に作成します。

Native Modulesで発生するエラーを個別にハンドリングする場合は、言語毎のエラー処理方式に従ってエラーを捕捉してください。

また、Native Modulesで発生したエラーをJavaScript側に伝えたい場面もあります。その場合は、JavaScript側からエラー時に実行したいコールバック関数を受け取るか、Native ModulesからPromiseを返却する方法があります。詳細は、React Nativeのドキュメントを参照してください。

- [Android - Callbacks](https://reactnative.dev/docs/native-modules-android#callbacks)
- [Android - Promises](https://reactnative.dev/docs/native-modules-android#promises)
- [iOS - Callbacks](https://reactnative.dev/docs/native-modules-ios#callbacks)
- [iOS - Promises](https://reactnative.dev/docs/native-modules-ios#promises)
